<?xml version="1.0" ?>
<!-- =================================================================================== -->
<!-- |    This document was autogenerated by xacro from rover_arm.urdf.xacro           | -->
<!-- |    EDITING THIS FILE BY HAND IS NOT RECOMMENDED                                 | -->
<!-- =================================================================================== -->
<robot name="rover_arm">
  <!--DEFINING ROBOT LINKS IN ORDER FROM BASE TO HAND-->
  <link name="base_link">
    <visual>
      <origin rpy="0 0 0" xyz="0 0 0"/>
      <geometry>
        <mesh filename="package://rover_arm_urdf/urdf/dae_files/base_link.dae"/>
      </geometry>
    </visual>
    <collision>
      <origin rpy="0 0 0" xyz="0 0 0"/>
      <geometry>
        <mesh filename="package://rover_arm_urdf/urdf/stl_files/base_link.stl"/>
      </geometry>
    </collision>
  </link>
  <link name="arm_link_0">
    <visual>
      <origin rpy="0 0 0" xyz="-0.043 -0.056 0"/>
      <geometry>
        <mesh filename="package://rover_arm_urdf/urdf/dae_files/arm_link_0.dae"/>
      </geometry>
    </visual>
    <collision>
      <origin rpy="0 0 0" xyz="-0.043 -0.056 0"/>
      <geometry>
        <mesh filename="package://rover_arm_urdf/urdf/stl_files/arm_link_0.stl"/>
      </geometry>
    </collision>
    <inertial>
      <mass value="1"/>
      <inertia ixx="1.0" ixy="0.0" ixz="0.0" iyy="1.0" iyz="0.0" izz="1.0"/>
    </inertial>
  </link>
  <link name="arm_link_1">
    <visual>
      <origin rpy="0 0 0" xyz="0 0 0"/>
      <geometry>
        <mesh filename="package://rover_arm_urdf/urdf/dae_files/arm_link_1.dae"/>
      </geometry>
    </visual>
    <collision>
      <origin rpy="0 0 0" xyz="0 0 0"/>
      <geometry>
        <mesh filename="package://rover_arm_urdf/urdf/stl_files/arm_link_1.stl"/>
      </geometry>
    </collision>
    <inertial>
      <mass value="1"/>
      <inertia ixx="1.0" ixy="0.0" ixz="0.0" iyy="1.0" iyz="0.0" izz="1.0"/>
    </inertial>
  </link>
  <link name="arm_link_2">
    <visual>
      <origin rpy="0 0 0" xyz="0.063 0.000654 -0.040895"/>
      <geometry>
        <mesh filename="package://rover_arm_urdf/urdf/dae_files/arm_link_2.dae"/>
      </geometry>
    </visual>
    <collision>
      <origin rpy="0 0 0" xyz="0.063 0.000654 -0.040895"/>
      <geometry>
        <mesh filename="package://rover_arm_urdf/urdf/stl_files/arm_link_2.stl"/>
      </geometry>
    </collision>
    <inertial>
      <mass value="1"/>
      <inertia ixx="1.0" ixy="0.0" ixz="0.0" iyy="1.0" iyz="0.0" izz="1.0"/>
    </inertial>
  </link>
  <link name="arm_link_3">
    <visual>
      <origin rpy="0 0 0" xyz="0 0 -0.0086"/>
      <geometry>
        <mesh filename="package://rover_arm_urdf/urdf/dae_files/arm_link_3.dae"/>
      </geometry>
    </visual>
    <collision>
      <origin rpy="0 0 0" xyz="0 0 -0.0086"/>
      <geometry>
        <mesh filename="package://rover_arm_urdf/urdf/stl_files/arm_link_3.stl"/>
      </geometry>
    </collision>
    <inertial>
      <mass value="1"/>
      <inertia ixx="1.0" ixy="0.0" ixz="0.0" iyy="1.0" iyz="0.0" izz="1.0"/>
    </inertial>
  </link>
  <link name="arm_link_4">
    <visual>
      <origin rpy="0 0 1.57079632679" xyz="0 0 0"/>
      <geometry>
        <mesh filename="package://rover_arm_urdf/urdf/dae_files/arm_link_4.dae"/>
      </geometry>
    </visual>
    <collision>
      <origin rpy="0 0 1.57079632679" xyz="0 0 0"/>
      <geometry>
        <mesh filename="package://rover_arm_urdf/urdf/stl_files/arm_link_4.stl"/>
      </geometry>
    </collision>
    <inertial>
      <mass value="1"/>
      <inertia ixx="1.0" ixy="0.0" ixz="0.0" iyy="1.0" iyz="0.0" izz="1.0"/>
    </inertial>
  </link>
  <link name="arm_gripper">
    <visual>
      <origin rpy="0 0 0" xyz="-0.038106 0.015875 0.14921"/>
      <geometry>
        <mesh filename="package://rover_arm_urdf/urdf/dae_files/arm_gripper.dae"/>
      </geometry>
    </visual>
    <collision>
      <origin rpy="0 0 0" xyz="-0.038106 0.015875 0.14921"/>
      <geometry>
        <mesh filename="package://rover_arm_urdf/urdf/stl_files/arm_gripper.stl"/>
      </geometry>
    </collision>
    <inertial>
      <mass value="1"/>
      <inertia ixx="1.0" ixy="0.0" ixz="0.0" iyy="1.0" iyz="0.0" izz="1.0"/>
    </inertial>
  </link>
  <joint name="base_joint" type="revolute">
    <parent link="base_link"/>
    <child link="arm_link_0"/>
    <origin rpy="0 0 0" xyz="0 0.055 0.087245"/>
    <axis xyz="0 0 -1"/>
    <limit effort="1000.0" lower="-1.57079632679" upper="1.57079632679" velocity="2.0"/>
  </joint>
  <joint name="shoulder_joint" type="revolute">
    <parent link="arm_link_0"/>
    <child link="arm_link_1"/>
    <origin rpy="0 0 3.14159" xyz="0 0 0.151443"/>
    <axis xyz="-1 0 0"/>
    <limit effort="1000.0" lower="-1.57079632679" upper="1.57079632679" velocity="2.0"/>
  </joint>
  <joint name="elbow_pitch_joint" type="revolute">
    <parent link="arm_link_1"/>
    <child link="arm_link_2"/>
    <origin rpy="0 0 0" xyz="0.05925 0 0.501983"/>
    <axis xyz="-1 0 0"/>
    <limit effort="1000.0" lower="-1.57079632679" upper="1.57079632679" velocity="2.0"/>
  </joint>
  <joint name="elbow_roll_joint" type="revolute">
    <parent link="arm_link_2"/>
    <child link="arm_link_3"/>
    <origin rpy="0 0 0" xyz="0.063 0.000654 0.059505"/>
    <axis xyz="0 0 -1"/>
    <limit effort="1000.0" lower="-3.141592653589793" upper="3.141592653589793" velocity="2.0"/>
  </joint>
  <joint name="wrist_pitch_joint" type="revolute">
    <parent link="arm_link_3"/>
    <child link="arm_link_4"/>
    <origin rpy="0 0 0" xyz="-0.065 0 0.3318"/>
    <axis xyz="-1 0 0"/>
    <limit effort="1000.0" lower="-1.57079632679" upper="3.141592653589793" velocity="2.0"/>
  </joint>
  <joint name="wrist_roll_joint" type="continuous">
    <parent link="arm_link_4"/>
    <child link="arm_gripper"/>
    <origin rpy="0 0 0" xyz="-0.050 0 0.050484"/>
    <axis xyz="0 0 1"/>
    <limit effort="1000.0" velocity="2.0"/>
  </joint>
  <material name="aluminum">
    <color rgba="0.5 0.5 0.5 1"/>
  </material>
  <material name="plastic">
    <color rgba="0.1 0.1 0.1 1"/>
  </material>
  <!-- camera body, with origin at bottom screw mount -->
  <joint name="camera_joint" type="fixed">
    <origin rpy="0 0 0" xyz="0 5 5"/>
    <parent link="arm_gripper"/>
    <child link="camera_bottom_screw_frame"/>
  </joint>
  <link name="camera_bottom_screw_frame"/>
  <joint name="camera_link_joint" type="fixed">
    <origin rpy="0 0 0" xyz="0.01085 0.009 0.021"/>
    <parent link="camera_bottom_screw_frame"/>
    <child link="camera_link"/>
  </joint>
  <link name="camera_link">
    <visual>
      <!-- the mesh origin is at front plate in between the two infrared camera axes -->
      <origin rpy="1.5707963267948966 0 1.5707963267948966" xyz="0.0038 -0.009 0"/>
      <geometry>
        <mesh filename="file:///opt/ros/humble/share/realsense2_description/meshes/d405.stl" scale="0.001 0.001 0.001"/>
      </geometry>
      <material name="aluminum"/>
    </visual>
    <collision>
      <origin rpy="0 0 0" xyz="-0.0078 -0.009 0"/>
      <geometry>
        <box size="0.023 0.042 0.042"/>
      </geometry>
    </collision>
    <inertial>
      <!-- The following are not reliable values, and should not be used for modeling -->
      <mass value="0.072"/>
      <origin xyz="0 0 0"/>
      <inertia ixx="0.003881243" ixy="0.0" ixz="0.0" iyy="0.000498940" iyz="0.0" izz="0.003879257"/>
    </inertial>
  </link>
  <!-- camera depth joints and links -->
  <joint name="camera_depth_joint" type="fixed">
    <origin rpy="0 0 0" xyz="0 0 0"/>
    <parent link="camera_link"/>
    <child link="camera_depth_frame"/>
  </joint>
  <link name="camera_depth_frame"/>
  <joint name="camera_depth_optical_joint" type="fixed">
    <origin rpy="-1.5707963267948966 0 -1.5707963267948966" xyz="0 0 0"/>
    <parent link="camera_depth_frame"/>
    <child link="camera_depth_optical_frame"/>
  </joint>
  <link name="camera_depth_optical_frame"/>
  <!-- camera left IR joints and links -->
  <joint name="camera_infra1_joint" type="fixed">
    <origin rpy="0 0 0" xyz="0 0.0 0"/>
    <parent link="camera_link"/>
    <child link="camera_infra1_frame"/>
  </joint>
  <link name="camera_infra1_frame"/>
  <joint name="camera_infra1_optical_joint" type="fixed">
    <origin rpy="-1.5707963267948966 0 -1.5707963267948966" xyz="0 0 0"/>
    <parent link="camera_infra1_frame"/>
    <child link="camera_infra1_optical_frame"/>
  </joint>
  <link name="camera_infra1_optical_frame"/>
  <!-- camera right IR joints and links -->
  <joint name="camera_infra2_joint" type="fixed">
    <origin rpy="0 0 0" xyz="0 -0.018 0"/>
    <parent link="camera_link"/>
    <child link="camera_infra2_frame"/>
  </joint>
  <link name="camera_infra2_frame"/>
  <joint name="camera_infra2_optical_joint" type="fixed">
    <origin rpy="-1.5707963267948966 0 -1.5707963267948966" xyz="0 0 0"/>
    <parent link="camera_infra2_frame"/>
    <child link="camera_infra2_optical_frame"/>
  </joint>
  <link name="camera_infra2_optical_frame"/>
  <!-- camera color joints and links -->
  <joint name="camera_color_joint" type="fixed">
    <origin rpy="0 0 0" xyz="0 0.0 0"/>
    <parent link="camera_link"/>
    <child link="camera_color_frame"/>
  </joint>
  <link name="camera_color_frame"/>
  <joint name="camera_color_optical_joint" type="fixed">
    <origin rpy="-1.5707963267948966 0 -1.5707963267948966" xyz="0 0 0"/>
    <parent link="camera_color_frame"/>
    <child link="camera_color_optical_frame"/>
  </joint>
  <link name="camera_color_optical_frame"/>
  <ros2_control name="RealSystem" type="system">
    <hardware>
      <plugin>odrive_ros2_control_plugin/ODriveHardwareInterface</plugin>
      <param name="can">can1</param>
      <!-- <plugin>mock_components/GenericSystem</plugin> -->
    </hardware>
    <joint name="base_joint">
      <param name="node_id">0</param>
      <param name="gear_ratio">400.0</param>
      <command_interface name="position"/>
      <command_interface name="velocity"/>
      <state_interface name="position">
        <param name="initial_value">0</param>
      </state_interface>
      <state_interface name="velocity"/>
      <state_interface name="effort"/>
    </joint>
    <joint name="shoulder_joint">
      <param name="node_id">1</param>
      <param name="gear_ratio">640.0</param>
      <command_interface name="position"/>
      <command_interface name="velocity"/>
      <state_interface name="position">
        <param name="initial_value">0</param>
      </state_interface>
      <state_interface name="velocity"/>
      <state_interface name="effort"/>
    </joint>
    <joint name="elbow_pitch_joint">
      <param name="node_id">2</param>
      <param name="gear_ratio">393.6</param>
      <command_interface name="position"/>
      <command_interface name="velocity"/>
      <state_interface name="position">
        <param name="initial_value">0</param>
      </state_interface>
      <state_interface name="velocity"/>
      <state_interface name="effort"/>
    </joint>
    <joint name="elbow_roll_joint">
      <param name="node_id">3</param>
      <param name="gear_ratio">120.0</param>
      <command_interface name="position"/>
      <command_interface name="velocity"/>
      <state_interface name="position">
        <param name="initial_value">0</param>
      </state_interface>
      <state_interface name="velocity"/>
      <state_interface name="effort"/>
    </joint>
    <joint name="wrist_pitch_joint">
      <param name="node_id">4</param>
      <param name="gear_ratio">370.0</param>
      <command_interface name="position"/>
      <command_interface name="velocity"/>
      <state_interface name="position">
        <param name="initial_value">0</param>
      </state_interface>
      <state_interface name="velocity"/>
      <state_interface name="effort"/>
    </joint>
    <joint name="wrist_roll_joint">
      <param name="node_id">5</param>
      <param name="gear_ratio">100.0</param>
      <command_interface name="position"/>
      <command_interface name="velocity"/>
      <state_interface name="position">
        <param name="initial_value">0</param>
      </state_interface>
      <state_interface name="velocity"/>
      <state_interface name="effort"/>
    </joint>
  </ros2_control>
</robot>
